concurrent.futures.process._RemoteTraceback:
"""
Traceback (most recent call last):
  File "/cvmfs/soft.computecanada.ca/easybuild/software/2023/x86-64-v3/Compiler/gcccore/python/3.12.4/lib/python3.12/concurrent/futures/process.py", line 263, in _process_worker
    r = call_item.fn(*call_item.args, **call_item.kwargs)
        ^^^^^^^^^^^^^^^^^^^^^^^^^^^^^^^^^^^^^^^^^^^^^^^^^
  File "/cvmfs/soft.computecanada.ca/easybuild/software/2023/x86-64-v3/Compiler/gcccore/python/3.12.4/lib/python3.12/concurrent/futures/process.py", line 212, in _process_chunk
    return [fn(*args) for args in chunk]
            ^^^^^^^^^
  File "/project/6000478/bobb/testDocker.py", line 49, in run_one_sim
    raise RuntimeError(f"Unexpected data shape {arr.shape} for {file_path}")
RuntimeError: Unexpected data shape (785, 9) for configTemplate.txt
"""

The above exception was the direct cause of the following exception:

Traceback (most recent call last):
  File "/project/6000478/bobb/testDocker.py", line 84, in <module>
    main()
  File "/project/6000478/bobb/testDocker.py", line 76, in main
    data = batch_run(file_list)
           ^^^^^^^^^^^^^^^^^^^^
  File "/project/6000478/bobb/testDocker.py", line 64, in batch_run
    tensors = list(executor.map(run_one_sim, file_list))
              ^^^^^^^^^^^^^^^^^^^^^^^^^^^^^^^^^^^^^^^^^^
  File "/cvmfs/soft.computecanada.ca/easybuild/software/2023/x86-64-v3/Compiler/gcccore/python/3.12.4/lib/python3.12/concurrent/futures/process.py", line 642, in _chain_from_iterable_of_lists
    for element in iterable:
  File "/cvmfs/soft.computecanada.ca/easybuild/software/2023/x86-64-v3/Compiler/gcccore/python/3.12.4/lib/python3.12/concurrent/futures/_base.py", line 619, in result_iterator
    yield _result_or_cancel(fs.pop())
          ^^^^^^^^^^^^^^^^^^^^^^^^^^^
  File "/cvmfs/soft.computecanada.ca/easybuild/software/2023/x86-64-v3/Compiler/gcccore/python/3.12.4/lib/python3.12/concurrent/futures/_base.py", line 317, in _result_or_cancel
    return fut.result(timeout)
           ^^^^^^^^^^^^^^^^^^^
  File "/cvmfs/soft.computecanada.ca/easybuild/software/2023/x86-64-v3/Compiler/gcccore/python/3.12.4/lib/python3.12/concurrent/futures/_base.py", line 456, in result
    return self.__get_result()
           ^^^^^^^^^^^^^^^^^^^
  File "/cvmfs/soft.computecanada.ca/easybuild/software/2023/x86-64-v3/Compiler/gcccore/python/3.12.4/lib/python3.12/concurrent/futures/_base.py", line 401, in __get_result
    raise self._exception
RuntimeError: Unexpected data shape (785, 9) for configTemplate.txt